Workbook

Sheet Sheet 1
A1: 0 for knowing exact meaning | B1: Participant 1 | C1: Participant 2 | D1: Participant 3 (Liu) | E1: Participant 4 | F1: Participant 5 | G1: Participant 6 | H1: Participant 7 | I1: Participant 8 | J1: Participant 9 (katherine) | K1: Participant 10 | L1: Unknown Word Count
A2: Have you studied for GRE? (Yes or No) | B2: No | C2: No | D2: Yes | E2: Yes | F2: Yes | G2: No | H2: No | I2: No | K2: No
A3: Macerate | L3: =COUNTIFS(B3:K3,"=0") -> 0
A4: Fulminate | J4: 0 | L4: =COUNTIFS(B4:K4,"=0") -> 1
A5: Headlong | L5: =COUNTIFS(B5:K5,"=0") -> 0
A6: Proselytize | J6: 0 | L6: =COUNTIFS(B6:K6,"=0") -> 1
A7: Burlesque | D7: 0 | J7: 0 | K7: 0 | L7: =COUNTIFS(B7:K7,"=0") -> 3
A8: Grotesque | B8: 0 | D8: 0 | J8: 0 | K8: 0 | L8: =COUNTIFS(B8:K8,"=0") -> 4
A9: Invective | F9: 0 | H9: 0 | J9: 0 | L9: =COUNTIFS(B9:K9,"=0") -> 3
A10: Piddling | D10: 0 | H10: 0 | L10: =COUNTIFS(B10:K10,"=0") -> 2
A11: Rash | B11: 0 | E11: 0 | H11: 0 | J11: 0 | K11: 0 | L11: =COUNTIFS(B11:K11,"=0") -> 5
A12: Seminal | B12: 0 | E12: 0 | F12: 0 | G12: 0 | I12: 0 | J12: 0 | K12: 0 | L12: =COUNTIFS(B12:K12,"=0") -> 7
A13: Subliminal | B13: 0 | C13: 0 | D13: 0 | E13: 0 | K13: 0 | L13: =COUNTIFS(B13:K13,"=0") -> 5
A14: Irksome | J14: 0 | K14: 0 | L14: =COUNTIFS(B14:K14,"=0") -> 2
A15: Revel | J15: 0 | L15: =COUNTIFS(B15:K15,"=0") -> 1
A16: Lurk | B16: 0 | H16: 0 | J16: 0 | K16: 0 | L16: =COUNTIFS(B16:K16,"=0") -> 4
A17: Agog | J17: 0 | K17: 0 | L17: =COUNTIFS(B17:K17,"=0") -> 2
A18: Requite | L18: =COUNTIFS(B18:K18,"=0") -> 0
A19: Sepulchral | J19: 0 | L19: =COUNTIFS(B19:K19,"=0") -> 1
A20: Mecurial | B20: 0 | D20: 0 | E20: 0 | F20: 0 | G20: 0 | K20: 0 | L20: =COUNTIFS(B20:K20,"=0") -> 6
A21: Abysmal | B21: 0 | D21: 0 | E21: 0 | G21: 0 | I21: 0 | J21: 0 | K21: 0 | L21: =COUNTIFS(B21:K21,"=0") -> 7
A22: Brook | F22: 0 | H22: 0 | J22: 0 | L22: =COUNTIFS(B22:K22,"=0") -> 3
A23: Appall | C23: 0 | D23: 0 | E23: 0 | K23: 0 | L23: =COUNTIFS(B23:K23,"=0") -> 4
A24: Jabber | L24: =COUNTIFS(B24:K24,"=0") -> 0
A25: Ominous | B25: 0 | C25: 0 | D25: 0 | J25: 0 | K25: 0 | L25: =COUNTIFS(B25:K25,"=0") -> 5
A26: Augur | J26: 0 | L26: =COUNTIFS(B26:K26,"=0") -> 1
A27: Paroxysm | K27: 0 | L27: =COUNTIFS(B27:K27,"=0") -> 1
A28: Don | F28: 0 | H28: 0 | L28: =COUNTIFS(B28:K28,"=0") -> 2
A29: Adjure | B29: 0 | E29: 0 | F29: 0 | J29: 0 | K29: 0 | L29: =COUNTIFS(B29:K29,"=0") -> 5
A30: Halcyon | J30: 0 | L30: =COUNTIFS(B30:K30,"=0") -> 1
A31: Dour | D31: 0 | H31: 0 | J31: 0 | L31: =COUNTIFS(B31:K31,"=0") -> 3
A32: Charlatan | C32: 0 | D32: 0 | J32: 0 | K32: 0 | L32: =COUNTIFS(B32:K32,"=0") -> 4
A33: Ragged | B33: 0 | K33: 0 | L33: =COUNTIFS(B33:K33,"=0") -> 2
A34: Kindred | B34: 0 | F34: 0 | H34: 0 | K34: 0 | L34: =COUNTIFS(B34:K34,"=0") -> 4
A35: Rabid | J35: 0 | L35: =COUNTIFS(B35:K35,"=0") -> 1
A36: Flaccid | B36: 0 | D36: 0 | E36: 0 | J36: 0 | K36: 0 | L36: =COUNTIFS(B36:K36,"=0") -> 5
A37: Sordid | C37: 0 | D37: 0 | J37: 0 | L37: =COUNTIFS(B37:K37,"=0") -> 3
A38: Vapid | C38: 0 | G38: 0 | J38: 0 | L38: =COUNTIFS(B38:K38,"=0") -> 3
A39: Hidebound | D39: 0 | E39: 0 | J39: 0 | L39: =COUNTIFS(B39:K39,"=0") -> 3
A40: Dullard | D40: 0 | L40: =COUNTIFS(B40:K40,"=0") -> 1
...

Sheet Sheet2
A1: ='Sheet 1'!A:A -> 0 for knowing exact meaning | B1: ='Sheet 1'!L:L -> Unknown Word Count | C1: Unknown Word Count
A2: ='Sheet 1'!A:A -> Have you studied for GRE? (Yes or No) | B2: ='Sheet 1'!L:L -> 0
A3: ='Sheet 1'!A:A -> Macerate | B3: ='Sheet 1'!L:L -> 0 | C3: 0
A4: ='Sheet 1'!A:A -> Fulminate | B4: ='Sheet 1'!L:L -> 1 | C4: 0
A5: ='Sheet 1'!A:A -> Headlong | B5: ='Sheet 1'!L:L -> 0 | C5: 0
A6: ='Sheet 1'!A:A -> Proselytize | B6: ='Sheet 1'!L:L -> 1 | C6: 0
A7: ='Sheet 1'!A:A -> Burlesque | B7: ='Sheet 1'!L:L -> 3 | C7: 0
A8: ='Sheet 1'!A:A -> Grotesque | B8: ='Sheet 1'!L:L -> 4 | C8: 0
A9: ='Sheet 1'!A:A -> Invective | B9: ='Sheet 1'!L:L -> 3 | C9: 0
A10: ='Sheet 1'!A:A -> Piddling | B10: ='Sheet 1'!L:L -> 2 | C10: 0
A11: ='Sheet 1'!A:A -> Rash | B11: ='Sheet 1'!L:L -> 5 | C11: 0
A12: ='Sheet 1'!A:A -> Seminal | B12: ='Sheet 1'!L:L -> 7 | C12: 0
A13: ='Sheet 1'!A:A -> Subliminal | B13: ='Sheet 1'!L:L -> 5 | C13: 0
A14: ='Sheet 1'!A:A -> Irksome | B14: ='Sheet 1'!L:L -> 2 | C14: 0
... A99: ='Sheet 1'!A:A -> Gregarious | B99: ='Sheet 1'!L:L -> 4 | C99: 7
